Workbook
Name SMS_print: #REF!
Name SMS_print: #REF!
Name SMS_print: #REF!
Name SMS_print: #REF!
Name SMS_print: #REF!
Name SMS_print: #REF!
Name SMS_print: #REF!
Name SMS_print: #REF!
Name SMS_print: #REF!

Sheet MEI 2026-07  ADA2 TOC
A1: MONTHLY ECONOMIC INDICATORS: STATE and COUNTIES_SEPTEMBER 2, 2026
A2: MONTH OF JULY 2026
A3: Table | B3: Table Name
A4: Seas-Adj. | B4: SEASONALLY ADJUSTED EMPLOYMENT AND JOB DATA
A5: State | B5: EMPLOYMENT AND JOB DATA: State
A6: Honolulu | B6: EMPLOYMENT AND JOB DATA: Honolulu
A7: Hawaii | B7: EMPLOYMENT AND JOB DATA: Hawaii County
A8: Maui | B8: EMPLOYMENT AND JOB DATA: Maui County
A9: Kauai | B9: EMPLOYMENT AND JOB DATA: Kauai County
A10: Tax Data, by Fiscal Year | B10: TAX DATA, BY FISCAL YEAR: State and counties

Sheet MEI 2026-07 ADA2 SA
A1: SEASONALLY ADJUSTED EMPLOYMENT AND JOB DATA: SEPTEMBER 2, 2026
A2: MONTH OF JULY 2026
A3: SERIES for State of Hawaii unless otherwise indicated | B3: JUNE 2026 | C3: JULY 2026 | D3: Month Percentage Change | E3: January 2026 through June 2026 YTD | F3: January 2026 through July 2026 YTD | G3: YTD Percentage Change
A4: Civilian labor force SA, persons (Level 1) [a] | B4: 690400 | C4: 690900 | D4: 0.072421784 | E4: 688500 | F4: 688850 | G4: 0.050835149
A5: Civilian employed SA (Level 2) [a] | B5: 672500 | C5: 672500 | D5: 0 | E5: 671950 | F5: 672050 | G5: 0.01488206
A6: Civilian unemployed SA (Level 2) [a] | B6: 17900 | C6: 18350 | D6: 2.5139665 | E6: 16550 | F6: 16800 | G6: 1.510574
A7: Unemployment rate SA [a] [b] | B7: 2.6 | C7: 2.7 | D7: 0.1 | E7: 2.4 | F7: 2.4 | G7: 0
A8: Total non-agriculture wage and salary jobs SA (Level 1) [a] | B8: 643200 | C8: 642700 | D8: -0.077736318 | E8: 643700 | F8: 643600 | G8: -0.015535187
A9: Mining Logging & Construction (Level 2) | B9: 41500 | C9: 41100 | D9: -0.96385542 | E9: 41200 | F9: 41200 | G9: 0
A10: Manufacturing (Level 2) | B10: 12900 | C10: 12600 | D10: -2.3255814 | E10: 13000 | F10: 13000 | G10: 0
A11: Durable Goods (Level 3) | B11: 3500 | C11: 3400 | D11: -2.8571429 | E11: 3500 | F11: 3500 | G11: 0
A12: Non-Durable Goods | B12: 9400 | C12: 9200 | D12: -2.1276596 | E12: 9500 | F12: 9500 | G12: 0
A13: Trade, Transp. & Utilities (Level 2) | B13: 115300 | C13: 114900 | D13: -0.34692108 | E13: 116100 | F13: 115900 | G13: -0.17226529
A14: Wholesale Trade (Level 3) | B14: 17300 | C14: 17200 | D14: -0.57803468 | E14: 17500 | F14: 17500 | G14: 0
A15: Retail Trade (Level 3) | B15: 63700 | C15: 63200 | D15: -0.78492936 | E15: 64200 | F15: 64000 | G15: -0.31152648
... A45: Maui Total Job Count | B45: 75300 | C45: 75300 | D45: 0 | E45: 75000 | F45: 75000 | G45: 0
A46: Seasonally-adjusted state and Honolulu and Maui jobs data for July 2026 preliminary were available on Septembet 2, 2026.
A47: [a] Labor force and job averages are based on monthly rounded data. SA Seasonally Adjusted.
A48: See Hawaii DBEDT <http://dbedt.hawaii.gov/economic/unemployment-statistics/> and <http://dbedt.hawaii.gov/economic/job-count-by-industry/> .
A49: [b] Change represents absolute change in rates rather than percentage change in rates.
A50: Source: Hawaii Department of Business, Economic Development & Tourism and U.S. Bureau of Labor Statistics.
A51: Final tables compiled by Statistics & Data Support Branch, READ, DBEDT

Sheet MEI 2026-07 ADA2 State
A1: MONTHLY ECONOMIC INDICATORS: STATE_AUGUST 27, 2026
A2: MONTH OF JULY 2026
A3: Category | B3: JULY 2025 | C3: JULY 2026 | D3: Month Percentage Change | E3: January 2025 through July 2025 YTD | F3: January 2026 through July 2026 YTD | G3: YTD Percentage Change
A4: Civilian labor force NSA, persons (Level 1) [a] | B4: 687900 | C4: 691350 | D4: 0.50152638 | E4: 688400 | F4: 689800 | G4: 0.20337013
A5: Civilian employed NSA (Level 2) [a] | B5: 672400 | C5: 671650 | D5: -0.11154075 | E5: 672000 | F5: 672350 | G5: 0.052083333
A6: Civilian unemployed NSA (Level 2) [a] | B6: 15550 | C6: 19700 | D6: 26.688103 | E6: 16400 | F6: 17500 | G6: 6.7073171
A7: Unemployment rate NSA [a] [b] | B7: 2.3 | C7: 2.9 | D7: 0.6 | E7: 2.4 | F7: 2.5 | G7: 0.1
A8: Total wage and salary jobs NSA (Level 1) [a] | B8: (NA) | C8: (NA) | D8: (NA) | E8: (NA) | F8: (NA) | G8: (NA)
A9: Total non-agriculture wage and salary jobs NSA (Level 2) | B9: 638100 | C9: 639100 | D9: 0.15671525 | E9: 642300 | F9: 643300 | G9: 0.15569049
A10: Natural Resources, Mining, Constr. (Level 3) | B10: 40400 | C10: 41400 | D10: 2.4752475 | E10: 39900 | F10: 41200 | G10: 3.2581454
A11: Manufacturing (Level 3) | B11: 13000 | C11: 12700 | D11: -2.3076923 | E11: 13000 | F11: 12900 | G11: -0.76923077
A12: Wholesale Trade (Level 3) | B12: 17200 | C12: 17200 | D12: 0 | E12: 17200 | F12: 17500 | G12: 1.744186
A13: Retail Trade (Level 3) | B13: 64000 | C13: 63100 | D13: -1.40625 | E13: 63800 | F13: 63600 | G13: -0.31347962
A14: Transportation, Warehousing, & Utilities (Level 3) | B14: 35300 | C14: 34500 | D14: -2.266289 | E14: 35100 | F14: 34400 | G14: -1.994302
A15: Information (Level 3) | B15: 6800 | C15: 7100 | D15: 4.4117647 | E15: 6900 | F15: 7000 | G15: 1.4492754
A16: Financial Activities (Level 3) | B16: 27200 | C16: 26300 | D16: -3.3088235 | E16: 27000 | F16: 26400 | G16: -2.2222222
A17: Prof. & Business Svcs. (Level 3) | B17: 72400 | C17: 72000 | D17: -0.55248619 | E17: 72600 | F17: 72600 | G17: 0
A18: Educational Services (Level 3) | B18: 14200 | C18: 14300 | D18: 0.70422535 | E18: 14700 | F18: 14700 | G18: 0
A19: Health Care/Social Assist. (Level 3) | B19: 76300 | C19: 79200 | D19: 3.8007864 | E19: 76300 | F19: 78400 | G19: 2.7522936
A20: Arts, Entert. Recreation (Level 3) | B20: 13400 | C20: 14000 | D20: 4.4776119 | E20: 13300 | F20: 13600 | G20: 2.2556391
... A27: Local Gov't (Level 4) | B27: 19600 | C27: 20500 | D27: 4.5918367 | E27: 19200 | F27: 19900 | G27: 3.6458333
A28: Agriculture wage and salary jobs NSA (Level 1) [a] | B28: (NA) | C28: (NA) | D28: (NA) | E28: (NA) | F28: (NA) | G28: (NA)
A29: State general fund tax revenues (Level 1) ($1,000) | B29: 755000.27 | C29: (NA) | D29: (NA) | E29: 5650834 | F29: (NA) | G29: (NA)
A30: General excise & use tax rev. (Level 2) ($1,000) | B30: 431543.14 | C30: 463441.84 | D30: 7.3917765 | E30: 2848813.1 | F30: 2943098.4 | G30: 3.3096333
A31: Income-individual ($1,000) (Level 2) | B31: 236125.24 | C31: 208357.05 | D31: -11.759945 | E31: 1831617.1 | F31: 1821861.3 | G31: -0.53263213
A32: Declaration estimated taxes (Level 3) | B32: 25049.728 | C32: 26632.903 | D32: 6.3201285 | E32: 671921.55 | F32: 693940.3 | G32: 3.276983
A33: Payment w/returns (Level 3) | B33: 14144.864 | C33: 8097.122 | D33: -42.755745 | E33: 341294.51 | F33: 342749.22 | G33: 0.42623393
A34: WH tax on wages (Level 3) | B34: 237215.41 | C34: 221082.36 | D34: -6.8010106 | E34: 1531642.9 | F34: 1447099.4 | G34: -5.5197971
A35: Refunds ('-' is relative to State) (Level 3) | B35: -40284.754 | C35: -47455.341 | D35: -17.799754 | E35: -713241.92 | F35: -661927.58 | G35: 7.1945202
A36: Transient accommodations tax (Level 2) ($1,000) | B36: 74454.546 | C36: 85506.664 | D36: 14.844114 | E36: 503974.68 | F36: 558994.84 | G36: 10.917248
A37: County surcharges ($1,000) (Level 2) [c] | B37: 51730.288 | C37: 55917.589 | D37: 8.0944862 | E37: 341678.69 | F37: 346978.59 | G37: 1.5511352
A38: Private Building Permits ($1,000) (Level 1) [d] [e] | B38: 402469.96 | C38: 163506.4 | D38: -59.374258 | E38: 3366915.9 | F38: 2223806 | G38: -33.951246
A39: Residential (Level 2) [d] [e] | B39: 178823.7 | C39: 135716.52 | D39: -24.105963 | E39: 1858000.6 | F39: 1023878.7 | G39: -44.893523
A40: Commercial & industrial (Level 2) [d] [e] [f] | B40: 82004.605 | C40: (NA) | D40: (NA) | E40: 400575.94 | F40: (NA) | G40: (NA)
A41: Additions & alterations (Level 2) [d] [e] [f] | B41: 141641.65 | C41: (NA) | D41: (NA) | E41: 1108339.4 | F41: (NA) | G41: (NA)
A42: Single-family home resales (Level 1) | B42: 506 | C42: 573 | D42: 13.241107 | E42: 3414 | F42: 3494 | G42: 2.3432923
A43: Median selling price (Level 2) | B43: (NA) | C43: (NA) | D43: (NA) | E43: (NA) | F43: (NA) | G43: (NA)
A44: Inventory (aver. units on market) (Level 2) [g] | B44: (NA) | C44: (NA) | D44: (NA) | E44: (NA) | F44: (NA) | G44: (NA)
A45: Condo/Apt/Townhouse units resales (Level 1) | B45: 505 | C45: 558 | D45: 10.49505 | E45: 3396 | F45: 3398 | G45: 0.058892815
A46: Median price (Level 2) | B46: (NA) | C46: (NA) | D46: (NA) | E46: (NA) | F46: (NA) | G46: (NA)
...

Sheet MEI 2026-07 ADA2 Hono
A1: ="MONTHLY ECONOMIC INDICATORS: "&I1&"_"&UPPER(TEXT(TODAY(),"MMMM d, yyyy")) -> MONTHLY ECONOMIC INDICATORS: _SEPTEMBER 2, 2026
A2: ='MEI 2026-07 ADA2 SA'!$A$2 -> MONTH OF JULY 2026
A3: SERIES | B3: ='MEI 2026-07 ADA2 State'!B3 -> JULY 2025 | C3: ='MEI 2026-07 ADA2 State'!C3 -> JULY 2026 | D3: ='MEI 2026-07 ADA2 State'!D3 -> Month Percentage Change | E3: ='MEI 2026-07 ADA2 State'!E3 -> January 2025 through July 2025 YTD | F3: ='MEI 2026-07 ADA2 State'!F3 -> January 2026 through July 2026 YTD | G3: ='MEI 2026-07 ADA2 State'!G3 -> YTD Percentage Change
A4: Civilian labor force NSA, persons (Level 1) [a] | B4: =[1]COMBO_frmls!PZ75 -> 474750 | C4: =[1]COMBO_frmls!QA75 -> 475650 | D4: =[1]COMBO_frmls!QB75 -> 0.18957346 | E4: =[1]COMBO_frmls!QC75 -> 476750 | F4: =[1]COMBO_frmls!QD75 -> 477000 | G4: =[1]COMBO_frmls!QE75 -> 0.052438385
A5: Civilian employed NSA (Level 2) [a] | B5: =[1]COMBO_frmls!PZ76 -> 464500 | C5: =[1]COMBO_frmls!QA76 -> 462500 | D5: =[1]COMBO_frmls!QB76 -> -0.43057051 | E5: =[1]COMBO_frmls!QC76 -> 465900 | F5: =[1]COMBO_frmls!QD76 -> 465350 | G5: =[1]COMBO_frmls!QE76 -> -0.11805108
A6: Civilian unemployed NSA (Level 2) [a] | B6: =[1]COMBO_frmls!PZ77 -> 10250 | C6: =[1]COMBO_frmls!QA77 -> 13200 | D6: =[1]COMBO_frmls!QB77 -> 28.780488 | E6: =[1]COMBO_frmls!QC77 -> 10850 | F6: =[1]COMBO_frmls!QD77 -> 11650 | G6: =[1]COMBO_frmls!QE77 -> 7.3732719
A7: Unemployment rate NSA [a] [b] | B7: =[1]COMBO_frmls!PZ78 -> 2.2 | C7: =[1]COMBO_frmls!QA78 -> 2.8 | D7: =[1]COMBO_frmls!QB78 -> 0.6 | E7: =[1]COMBO_frmls!QC78 -> 2.3 | F7: =[1]COMBO_frmls!QD78 -> 2.4 | G7: =[1]COMBO_frmls!QE78 -> 0.1
A8: Total wage and salary jobs NSA (Level 1) [a] | B8: (NA) | C8: (NA) | D8: (NA) | E8: (NA) | F8: (NA) | G8: (NA)
A9: Total non-agriculture wage and salary jobs NSA (Level 2) | B9: =[1]COMBO_frmls!PZ81 -> 457700 | C9: =[1]COMBO_frmls!QA81 -> 457200 | D9: =[1]COMBO_frmls!QB81 -> -0.10924186 | E9: =[1]COMBO_frmls!QC81 -> 462200 | F9: =[1]COMBO_frmls!QD81 -> 462000 | G9: =[1]COMBO_frmls!QE81 -> -0.043271311
A10: Natural Resources, Mining, Constr. (Level 3) | B10: =[1]COMBO_frmls!PZ82 -> 29200 | C10: =[1]COMBO_frmls!QA82 -> 29700 | D10: =[1]COMBO_frmls!QB82 -> 1.7123288 | E10: =[1]COMBO_frmls!QC82 -> 28800 | F10: =[1]COMBO_frmls!QD82 -> 29500 | G10: =[1]COMBO_frmls!QE82 -> 2.4305556
A11: Manufacturing (Level 3) | B11: =[1]COMBO_frmls!PZ83 -> 9700 | C11: =[1]COMBO_frmls!QA83 -> 9600 | D11: =[1]COMBO_frmls!QB83 -> -1.0309278 | E11: =[1]COMBO_frmls!QC83 -> 9700 | F11: =[1]COMBO_frmls!QD83 -> 9700 | G11: =[1]COMBO_frmls!QE83 -> 0
A12: Wholesale Trade (Level 3) | B12: =[1]COMBO_frmls!PZ84 -> 13600 | C12: =[1]COMBO_frmls!QA84 -> 13600 | D12: =[1]COMBO_frmls!QB84 -> 0 | E12: =[1]COMBO_frmls!QC84 -> 13600 | F12: =[1]COMBO_frmls!QD84 -> 13900 | G12: =[1]COMBO_frmls!QE84 -> 2.2058824
A13: Retail Trade (Level 3) | B13: =[1]COMBO_frmls!PZ85 -> 41500 | C13: =[1]COMBO_frmls!QA85 -> 40700 | D13: =[1]COMBO_frmls!QB85 -> -1.9277108 | E13: =[1]COMBO_frmls!QC85 -> 41400 | F13: =[1]COMBO_frmls!QD85 -> 41100 | G13: =[1]COMBO_frmls!QE85 -> -0.72463768
A14: Transportation, Warehousing, & Utilities (Level 3) | B14: =[1]COMBO_frmls!PZ86 -> 26200 | C14: =[1]COMBO_frmls!QA86 -> 25600 | D14: =[1]COMBO_frmls!QB86 -> -2.2900763 | E14: =[1]COMBO_frmls!QC86 -> 25900 | F14: =[1]COMBO_frmls!QD86 -> 25500 | G14: =[1]COMBO_frmls!QE86 -> -1.5444015
A15: Information (Level 3) | B15: =[1]COMBO_frmls!PZ87 -> 5500 | C15: =[1]COMBO_frmls!QA87 -> 5700 | D15: =[1]COMBO_frmls!QB87 -> 3.6363636 | E15: =[1]COMBO_frmls!QC87 -> 5600 | F15: =[1]COMBO_frmls!QD87 -> 5700 | G15: =[1]COMBO_frmls!QE87 -> 1.7857143
A16: Financial Activities (Level 3) | B16: =[1]COMBO_frmls!PZ88 -> 20800 | C16: =[1]COMBO_frmls!QA88 -> 19900 | D16: =[1]COMBO_frmls!QB88 -> -4.3269231 | E16: =[1]COMBO_frmls!QC88 -> 20600 | F16: =[1]COMBO_frmls!QD88 -> 20100 | G16: =[1]COMBO_frmls!QE88 -> -2.4271845
A17: Prof. & Business Svcs. (Level 3) | B17: =[1]COMBO_frmls!PZ89 -> 56000 | C17: =[1]COMBO_frmls!QA89 -> 55900 | D17: =[1]COMBO_frmls!QB89 -> -0.17857143 | E17: =[1]COMBO_frmls!QC89 -> 56200 | F17: =[1]COMBO_frmls!QD89 -> 56500 | G17: =[1]COMBO_frmls!QE89 -> 0.53380783
A18: Educational Services (Level 3) | B18: =[1]COMBO_frmls!PZ90 -> 11300 | C18: =[1]COMBO_frmls!QA90 -> 11400 | D18: =[1]COMBO_frmls!QB90 -> 0.88495575 | E18: =[1]COMBO_frmls!QC90 -> 11700 | F18: =[1]COMBO_frmls!QD90 -> 11700 | G18: =[1]COMBO_frmls!QE90 -> 0
A19: Health Care/Social Assist. (Level 3) | B19: =[1]COMBO_frmls!PZ91 -> 57200 | C19: =[1]COMBO_frmls!QA91 -> 59400 | D19: =[1]COMBO_frmls!QB91 -> 3.8461538 | E19: =[1]COMBO_frmls!QC91 -> 57200 | F19: =[1]COMBO_frmls!QD91 -> 58800 | G19: =[1]COMBO_frmls!QE91 -> 2.7972028
A20: Arts, Entert. Recreation (Level 3) | B20: =[1]COMBO_frmls!PZ92 -> 8300 | C20: =[1]COMBO_frmls!QA92 -> 8700 | D20: =[1]COMBO_frmls!QB92 -> 4.8192771 | E20: =[1]COMBO_frmls!QC92 -> 8300 | F20: =[1]COMBO_frmls!QD92 -> 8500 | G20: =[1]COMBO_frmls!QE92 -> 2.4096386
... A27: Local Gov't (Level 4) | B27: =[1]COMBO_frmls!PZ99 -> 12200 | C27: =[1]COMBO_frmls!QA99 -> 12700 | D27: =[1]COMBO_frmls!QB99 -> 4.0983607 | E27: =[1]COMBO_frmls!QC99 -> 12100 | F27: =[1]COMBO_frmls!QD99 -> 12500 | G27: =[1]COMBO_frmls!QE99 -> 3.3057851
A28: Agriculture wage and salary jobs NSA (Level 1) [a] | B28: (NA) | C28: (NA) | D28: (NA) | E28: (NA) | F28: (NA) | G28: (NA)
A29: General excise & use tax rev. ($1,000) (Level 1) | B29: (NA) | C29: (NA) | D29: (NA) | E29: (NA) | F29: (NA) | G29: (NA)
A30: Income-individual ($1,000) (Level 1) | B30: (NA) | C30: (NA) | D30: (NA) | E30: (NA) | F30: (NA) | G30: (NA)
A31: Declaration estimated taxes (Level 2) | B31: (NA) | C31: (NA) | D31: (NA) | E31: (NA) | F31: (NA) | G31: (NA)
A32: Payment w/returns (Level 2) | B32: (NA) | C32: (NA) | D32: (NA) | E32: (NA) | F32: (NA) | G32: (NA)
A33: WH tax on wages (Level 2) | B33: (NA) | C33: (NA) | D33: (NA) | E33: (NA) | F33: (NA) | G33: (NA)
A34: Refunds ('-' is relative to State) (Level 2) | B34: (NA) | C34: (NA) | D34: (NA) | E34: (NA) | F34: (NA) | G34: (NA)
A35: Transient accommodations tax ($1,000) (Level 1) | B35: (NA) | C35: (NA) | D35: (NA) | E35: (NA) | F35: (NA) | G35: (NA)
A36: County surcharges ($1,000) (Level 1) [c] | B36: =[1]COMBO_frmls!PZ110 -> 33384.829 | C36: =[1]COMBO_frmls!QA110 -> 35738.05 | D36: =[1]COMBO_frmls!QB110 -> 7.048772 | E36: =[1]COMBO_frmls!QC110 -> 217456.45 | F36: =[1]COMBO_frmls!QD110 -> 217167.57 | G36: =[1]COMBO_frmls!QE110 -> -0.13284484
A37: ='MEI 2026-07 ADA2 State'!A38 -> Private Building Permits ($1,000) (Level 1) [d] [e] | B37: =[1]COMBO_frmls!PZ112 -> 198810.62 | C37: =[1]COMBO_frmls!QA112 -> 45217.07 | D37: =[1]COMBO_frmls!QB112 -> -77.256209 | E37: =[1]COMBO_frmls!QC112 -> 2203941.1 | F37: =[1]COMBO_frmls!QD112 -> 1326153 | G37: =[1]COMBO_frmls!QE112 -> -39.828107
A38: ='MEI 2026-07 ADA2 State'!A39 -> Residential (Level 2) [d] [e] | B38: =[1]COMBO_frmls!PZ113 -> 86229.787 | C38: =[1]COMBO_frmls!QA113 -> 45217.07 | D38: =[1]COMBO_frmls!QB113 -> -47.562123 | E38: =[1]COMBO_frmls!QC113 -> 1121196.7 | F38: =[1]COMBO_frmls!QD113 -> 474512.24 | G38: =[1]COMBO_frmls!QE113 -> -57.678057
A39: ='MEI 2026-07 ADA2 State'!A40 -> Commercial & industrial (Level 2) [d] [e] [f] | B39: =[1]COMBO_frmls!PZ114 -> 2130.1629 | C39: (NA) | D39: (NA) | E39: =[1]COMBO_frmls!QC114 -> 198470.52 | F39: (NA) | G39: (NA)
A40: ='MEI 2026-07 ADA2 State'!A41 -> Additions & alterations (Level 2) [d] [e] [f] | B40: =[1]COMBO_frmls!PZ115 -> 110450.66 | C40: (NA) | D40: (NA) | E40: =[1]COMBO_frmls!QC115 -> 884273.82 | F40: (NA) | G40: (NA)
A41: ='MEI 2026-07 ADA2 State'!A42 -> Single-family home resales (Level 1) | B41: =[1]COMBO_frmls!PZ117 -> 249 | C41: =[1]COMBO_frmls!QA117 -> 300 | D41: =[1]COMBO_frmls!QB117 -> 20.481928 | E41: =[1]COMBO_frmls!QC117 -> 1583 | F41: =[1]COMBO_frmls!QD117 -> 1686 | G41: =[1]COMBO_frmls!QE117 -> 6.506633
A42: ='MEI 2026-07 ADA2 State'!A43 -> Median selling price (Level 2) | B42: =[1]COMBO_frmls!PZ118 -> 1075000 | C42: =[1]COMBO_frmls!QA118 -> 1224500 | D42: =[1]COMBO_frmls!QB118 -> 13.906977 | E42: =[1]COMBO_frmls!QC118 -> 1150000 | F42: =[1]COMBO_frmls!QD118 -> 1185000 | G42: =[1]COMBO_frmls!QE118 -> 3.0434783
A43: ='MEI 2026-07 ADA2 State'!A44 -> Inventory (aver. units on market) (Level 2) [g] | B43: =[1]COMBO_frmls!PZ119 -> 852 | C43: =[1]COMBO_frmls!QA119 -> 802 | D43: =[1]COMBO_frmls!QB119 -> -5.8685446 | E43: =[1]COMBO_frmls!QC119 -> 795.85714 | F43: =[1]COMBO_frmls!QD119 -> 722.57143 | G43: =[1]COMBO_frmls!QE119 -> -9.2084006
A44: ='MEI 2026-07 ADA2 State'!A45 -> Condo/Apt/Townhouse units resales (Level 1) | B44: =[1]COMBO_frmls!PZ120 -> 389 | C44: =[1]COMBO_frmls!QA120 -> 416 | D44: =[1]COMBO_frmls!QB120 -> 6.940874 | E44: =[1]COMBO_frmls!QC120 -> 2490 | F44: =[1]COMBO_frmls!QD120 -> 2469 | G44: =[1]COMBO_frmls!QE120 -> -0.84337349
A45: ='MEI 2026-07 ADA2 State'!A46 -> Median price (Level 2) | B45: =[1]COMBO_frmls!PZ121 -> 490000 | C45: =[1]COMBO_frmls!QA121 -> 504500 | D45: =[1]COMBO_frmls!QB121 -> 2.9591837 | E45: =[1]COMBO_frmls!QC121 -> 500765 | F45: =[1]COMBO_frmls!QD121 -> 513386 | G45: =[1]COMBO_frmls!QE121 -> 2.5203439
A46: ='MEI 2026-07 ADA2 State'!A47 -> Inventory (aver. units on market) (Level 2) [g] | B46: =[1]COMBO_frmls!PZ122 -> 2459 | C46: =[1]COMBO_frmls!QA122 -> 2554 | D46: =[1]COMBO_frmls!QB122 -> 3.8633591 | E46: =[1]COMBO_frmls!QC122 -> 2374.1429 | F46: =[1]COMBO_frmls!QD122 -> 2371.2857 | G46: =[1]COMBO_frmls!QE122 -> -0.12034418
...

Sheet MEI 2026-07 ADA2 Hawaii
A1: MONTHLY ECONOMIC INDICATORS: HAWAII_AUGUST 27, 2026
A2: MONTH OF JULY 2026
A3: SERIES | B3: JULY 2025 | C3: JULY 2026 | D3: Month Percentage Change | E3: January 2025 through July 2025 YTD | F3: January 2026 through July 2026 YTD | G3: YTD Percentage Change
A4: Civilian labor force NSA, persons (Level 1) (Note 1) | B4: 92300 | C4: 93100 | D4: 0.86673889 | E4: 91950 | F4: 92350 | G4: 0.43501903
A5: Civilian employed NSA (Level 2) (Note 1) | B5: 89800 | C5: 89900 | D5: 0.11135857 | E5: 89450 | F5: 89550 | G5: 0.1117943
A6: Civilian unemployed NSA (Level 2) (Note 1) | B6: 2500 | C6: 3250 | D6: 30 | E6: 2500 | F6: 2800 | G6: 12
A7: Unemployment rate NSA (Note 1, 2) | B7: 2.7 | C7: 3.5 | D7: 0.8 | E7: 2.7 | F7: 3 | G7: 0.3
A8: Total wage and salary jobs NSA (Level 1) (Note 1) | B8: (NA) | C8: (NA) | D8: (NA) | E8: (NA) | F8: (NA) | G8: (NA)
A9: Total non-agriculture wage and salary jobs NSA (Level 2) | B9: 72500 | C9: 72800 | D9: 0.4137931 | E9: 72900 | F9: 73100 | G9: 0.27434842
A10: Natural Resources, Mining, Constr. (Level 3) | B10: 4100 | C10: 4200 | D10: 2.4390244 | E10: 4100 | F10: 4200 | G10: 2.4390244
A11: Manufacturing (Level 3) | B11: 1600 | C11: 1600 | D11: 0 | E11: 1700 | F11: 1600 | G11: -5.8823529
A12: Wholesale Trade (Level 3) | B12: 1800 | C12: 1800 | D12: 0 | E12: 1800 | F12: 1800 | G12: 0
A13: Retail Trade (Level 3) | B13: 10200 | C13: 10100 | D13: -0.98039216 | E13: 10100 | F13: 10200 | G13: 0.99009901
A14: Transportation, Warehousing, & Utilities (Level 3) | B14: 3300 | C14: 3200 | D14: -3.030303 | E14: 3300 | F14: 3200 | G14: -3.030303
A15: Information (Level 3) | B15: 600 | C15: 600 | D15: 0 | E15: 600 | F15: 600 | G15: 0
A16: Financial Activities (Level 3) | B16: 2600 | C16: 2600 | D16: 0 | E16: 2600 | F16: 2600 | G16: 0
A17: Prof. & Business Svcs. (Level 3) | B17: 6200 | C17: 6100 | D17: -1.6129032 | E17: 6200 | F17: 6100 | G17: -1.6129032
A18: Educational Services (Level 3) | B18: 1400 | C18: 1300 | D18: -7.1428571 | E18: 1400 | F18: 1400 | G18: 0
A19: Health Care/Social Assist. (Level 3) | B19: 8200 | C19: 8300 | D19: 1.2195122 | E19: 8100 | F19: 8400 | G19: 3.7037037
A20: Arts, Entert. Recreation (Level 3) | B20: 1700 | C20: 1900 | D20: 11.764706 | E20: 1700 | F20: 1700 | G20: 0
... A27: Local Gov't (Level 4) | B27: 2900 | C27: 2900 | D27: 0 | E27: 2800 | F27: 2900 | G27: 3.5714286
A28: Agriculture wage and salary jobs NSA (Level 1) (Note 1) | B28: (NA) | C28: (NA) | D28: (NA) | E28: (NA) | F28: (NA) | G28: (NA)
A29: General excise & use tax rev. ($1,000) (Level 1) | B29: (NA) | C29: (NA) | D29: (NA) | E29: (NA) | F29: (NA) | G29: (NA)
A30: Income-individual ($1,000) (Level 1) | B30: (NA) | C30: (NA) | D30: (NA) | E30: (NA) | F30: (NA) | G30: (NA)
A31: Declaration estimated taxes (Level 2) | B31: (NA) | C31: (NA) | D31: (NA) | E31: (NA) | F31: (NA) | G31: (NA)
A32: Payment w/returns (Level 2) | B32: (NA) | C32: (NA) | D32: (NA) | E32: (NA) | F32: (NA) | G32: (NA)
A33: WH tax on wages (Level 2) | B33: (NA) | C33: (NA) | D33: (NA) | E33: (NA) | F33: (NA) | G33: (NA)
A34: Refunds ('-' is relative to State) (Level 2) | B34: (NA) | C34: (NA) | D34: (NA) | E34: (NA) | F34: (NA) | G34: (NA)
A35: Transient accommodations tax ($1,000) (Level 1) | B35: (NA) | C35: (NA) | D35: (NA) | E35: (NA) | F35: (NA) | G35: (NA)
A36: County surcharges ($1,000) (Level 1) (Note 3) | B36: 33384.829 | C36: 7506.022 | D36: -77.516668 | E36: 46781.239 | F36: 49297.821 | G36: 5.3794686
A37: Private Building Permits ($1,000) (Level 1) [d] [e] | B37: 88384.268 | C37: 78518.948 | D37: -11.16185 | E37: 603379.02 | F37: 545006.74 | G37: -9.6742309
A38: Residential (Level 2) [d] [e] | B38: 53866.411 | C38: 50729.067 | D38: -5.8243046 | E38: 402224.37 | F38: 303611.54 | G38: -24.51687
A39: Commercial & industrial (Level 2) [d] [e] [f] | B39: 8371.349 | C39: 4216.464 | D39: -49.632204 | E39: 41475.493 | F39: 46201.743 | G39: 11.395283
A40: Additions & alterations (Level 2) [d] [e] [f] | B40: 26146.507 | C40: 23573.417 | D40: -9.8410473 | E40: 159679.16 | F40: 195193.46 | G40: 22.241033
A41: Single-family home resales (Level 1) | B41: 163 | C41: 183 | D41: 12.269939 | E41: 1189 | F41: 1179 | G41: -0.84104289
A42: Median selling price (Level 2) | B42: 525000 | C42: 535000 | D42: 1.9047619 | E42: 565000 | F42: 560000 | G42: -0.88495575
A43: Inventory (aver. units on market) (Level 2) [g] | B43: (NA) | C43: (NA) | D43: (NA) | E43: (NA) | F43: (NA) | G43: (NA)
A44: Condo/Apt/Townhouse units resales (Level 1) | B44: 43 | C44: 42 | D44: -2.3255814 | E44: 320 | F44: 315 | G44: -1.5625
A45: Median price (Level 2) | B45: 620000 | C45: 838750 | D45: 35.282258 | E45: 646000 | F45: 625000 | G45: -3.250774
A46: Inventory (aver. units on market) (Level 2) [g] | B46: (NA) | C46: (NA) | D46: (NA) | E46: (NA) | F46: (NA) | G46: (NA)
...

Sheet MEI 2026-07 ADA2 Maui
A1: MONTHLY ECONOMIC INDICATORS: MAUI_AUGUST 27, 2026
A2: MONTH OF JULY 2026
A3: SERIES | B3: JULY 2025 | C3: JULY 2026 | D3: Month Percentage Change | E3: January 2025 through July 2025 YTD | F3: January 2026 through July 2026 YTD | G3: YTD Percentage Change
A4: Civilian labor force NSA, persons (Level 1) (Note 1) | B4: 82600 | C4: 84000 | D4: 1.6949153 | E4: 82000 | F4: 82700 | G4: 0.85365854
A5: Civilian employed NSA (Level 2) (Note 1) | B5: 80600 | C5: 81600 | D5: 1.2406948 | E5: 79700 | F5: 80500 | G5: 1.0037641
A6: Civilian unemployed NSA (Level 2) (Note 1) | B6: 2000 | C6: 2400 | D6: 20 | E6: 2250 | F6: 2200 | G6: -2.2222222
A7: Unemployment rate NSA (Note 1, 2) | B7: 2.4 | C7: 2.8 | D7: 0.4 | E7: 2.8 | F7: 2.6 | G7: -0.2
A8: Total wage and salary jobs NSA (Level 1) (Note 1) | B8: (NA) | C8: (NA) | D8: (NA) | E8: (NA) | F8: (NA) | G8: (NA)
A9: Total non-agriculture wage and salary jobs NSA (Level 2) | B9: 74200 | C9: 75500 | D9: 1.7520216 | E9: 74000 | F9: 75100 | G9: 1.4864865
A10: Natural Resources, Mining, Constr. (Level 3) | B10: 4900 | C10: 5200 | D10: 6.122449 | E10: 4800 | F10: 5100 | G10: 6.25
A11: Manufacturing (Level 3) | B11: 1000 | C11: 1000 | D11: 0 | E11: 1000 | F11: 1000 | G11: 0
A12: Wholesale Trade (Level 3) | B12: 1400 | C12: 1400 | D12: 0 | E12: 1400 | F12: 1400 | G12: 0
A13: Retail Trade (Level 3) | B13: 8500 | C13: 8500 | D13: 0 | E13: 8500 | F13: 8500 | G13: 0
A14: Transportation, Warehousing, & Utilities (Level 3) | B14: 4000 | C14: 4000 | D14: 0 | E14: 4100 | F14: 4000 | G14: -2.4390244
A15: Information (Level 3) | B15: 500 | C15: 500 | D15: 0 | E15: 500 | F15: 500 | G15: 0
A16: Financial Activities (Level 3) | B16: 2700 | C16: 2600 | D16: -3.7037037 | E16: 2700 | F16: 2700 | G16: 0
A17: Prof. & Business Svcs. (Level 3) | B17: 7100 | C17: 7000 | D17: -1.4084507 | E17: 7100 | F17: 7100 | G17: 0
A18: Educational Services (Level 3) | B18: 1300 | C18: 1300 | D18: 0 | E18: 1300 | F18: 1300 | G18: 0
A19: Health Care/Social Assist. (Level 3) | B19: 8100 | C19: 8400 | D19: 3.7037037 | E19: 8200 | F19: 8300 | G19: 1.2195122
A20: Arts, Entert. Recreation (Level 3) | B20: 2100 | C20: 2400 | D20: 14.285714 | E20: 2000 | F20: 2300 | G20: 15
... A27: Local Gov't (Level 4) | B27: 3000 | C27: 3200 | D27: 6.6666667 | E27: 2800 | F27: 3000 | G27: 7.1428571
A28: Agriculture wage and salary jobs NSA (Level 1) (Note 1) | B28: (NA) | C28: (NA) | D28: (NA) | E28: (NA) | F28: (NA) | G28: (NA)
A29: General excise & use tax rev. ($1,000) (Level 1) | B29: (NA) | C29: (NA) | D29: (NA) | E29: (NA) | F29: (NA) | G29: (NA)
A30: Income-individual ($1,000) (Level 1) | B30: (NA) | C30: (NA) | D30: (NA) | E30: (NA) | F30: (NA) | G30: (NA)
A31: Declaration estimated taxes (Level 2) | B31: (NA) | C31: (NA) | D31: (NA) | E31: (NA) | F31: (NA) | G31: (NA)
A32: Payment w/returns (Level 2) | B32: (NA) | C32: (NA) | D32: (NA) | E32: (NA) | F32: (NA) | G32: (NA)
A33: WH tax on wages (Level 2) | B33: (NA) | C33: (NA) | D33: (NA) | E33: (NA) | F33: (NA) | G33: (NA)
A34: Refunds ('-' is relative to State) (Level 2) | B34: (NA) | C34: (NA) | D34: (NA) | E34: (NA) | F34: (NA) | G34: (NA)
A35: Transient accommodations tax ($1,000) (Level 1) | B35: (NA) | C35: (NA) | D35: (NA) | E35: (NA) | F35: (NA) | G35: (NA)
A36: County surcharges ($1,000) (Level 1) (Note 3) | B36: 7748.7947 | C36: 8694.077 | D36: 12.199088 | E36: 54169.364 | F36: 56372.437 | G36: 4.0670088
A37: Private Building Permits ($1,000) (Level 1) [d] [e] | B37: 105675.89 | C37: 27056.791 | D37: -74.396439 | E37: 485983.83 | F37: 276091.61 | G37: -43.189138
A38: Residential (Level 2) [d] [e] | B38: 29128.315 | C38: 27056.791 | D38: -7.1117193 | E38: 260967.53 | F38: 169200.28 | G38: -35.164241
A39: Commercial & industrial (Level 2) [d] [e] [f] | B39: 71503.093 | C39: 0 | D39: -100 | E39: 160629.93 | F39: 28440.131 | G39: -82.294625
A40: Additions & alterations (Level 2) [d] [e] [f] | B40: 5044.482 | C40: 0 | D40: -100 | E40: 64386.379 | F40: 78451.198 | G40: 21.844401
A41: Single-family home resales (Level 1) | B41: 60 | C41: 55 | D41: -8.3333333 | E41: 409 | F41: 419 | G41: 2.4449878
A42: Median selling price (Level 2) | B42: 1315000 | C42: 1150000 | D42: -12.547529 | E42: 1300000 | F42: 1228000 | G42: -5.5384615
A43: Inventory (aver. units on market) (Level 2) [g] | B43: 450 | C43: 469 | D43: 4.2222222 | E43: 436.42857 | F43: 462 | G43: 5.8592471
A44: Condo/Apt/Townhouse units resales (Level 1) | B44: 53 | C44: 82 | D44: 54.716981 | E44: 409 | F44: 477 | G44: 16.625917
A45: Median price (Level 2) | B45: 675000 | C45: 690000 | D45: 2.2222222 | E45: 732000 | F45: 660000 | G45: -9.8360656
A46: Inventory (aver. units on market) (Level 2) [g] | B46: 882 | C46: 878 | D46: -0.45351474 | E46: 876.14286 | F46: 927 | G46: 5.8046633
...

Sheet MEI 2026-07 ADA2 Kauai
A1: MONTHLY ECONOMIC INDICATORS: KAUAI_AUGUST 27, 2026
A2: MONTH OF JULY 2026
A3: SERIES | B3: JULY 2025 | C3: JULY 2026 | D3: Month Percentage Change | E3: January 2025 through July 2025 YTD | F3: January 2026 through July 2026 YTD | G3: YTD Percentage Change
A4: Civilian labor force NSA, persons (Level 1) (Note 1) | B4: 38250 | C4: 38600 | D4: 0.91503268 | E4: 37700 | F4: 37800 | G4: 0.26525199
A5: Civilian employed NSA (Level 2) (Note 1) | B5: 37450 | C5: 37650 | D5: 0.53404539 | E5: 36900 | F5: 36900 | G5: 0
A6: Civilian unemployed NSA (Level 2) (Note 1) | B6: 750 | C6: 950 | D6: 26.666667 | E6: 800 | F6: 900 | G6: 12.5
A7: Unemployment rate NSA (Note 1, 2) | B7: 2 | C7: 2.4 | D7: 0.4 | E7: 2.2 | F7: 2.3 | G7: 0.1
A8: Total wage and salary jobs NSA (Level 1) (Note 1) | B8: (NA) | C8: (NA) | D8: (NA) | E8: (NA) | F8: (NA) | G8: (NA)
A9: Total non-agriculture wage and salary jobs NSA (Level 2) | B9: 33300 | C9: 33600 | D9: 0.9009009 | E9: 33000 | F9: 33100 | G9: 0.3030303
A10: Natural Resources, Mining, Constr. (Level 3) | B10: 2200 | C10: 2400 | D10: 9.0909091 | E10: 2200 | F10: 2300 | G10: 4.5454545
A11: Manufacturing (Level 3) | B11: 600 | C11: 600 | D11: 0 | E11: 600 | F11: 600 | G11: 0
A12: Wholesale Trade (Level 3) | B12: 500 | C12: 500 | D12: 0 | E12: 500 | F12: 500 | G12: 0
A13: Retail Trade (Level 3) | B13: 3800 | C13: 3800 | D13: 0 | E13: 3800 | F13: 3800 | G13: 0
A14: Transportation, Warehousing, & Utilities (Level 3) | B14: 1800 | C14: 1800 | D14: 0 | E14: 1800 | F14: 1800 | G14: 0
A15: Information (Level 3) | B15: 200 | C15: 200 | D15: 0 | E15: 200 | F15: 200 | G15: 0
A16: Financial Activities (Level 3) | B16: 1100 | C16: 1100 | D16: 0 | E16: 1100 | F16: 1100 | G16: 0
A17: Prof. & Business Svcs. (Level 3) | B17: 3000 | C17: 3100 | D17: 3.3333333 | E17: 3000 | F17: 3000 | G17: 0
A18: Educational Services (Level 3) | B18: 200 | C18: 200 | D18: 0 | E18: 300 | F18: 300 | G18: 0
A19: Health Care/Social Assist. (Level 3) | B19: 2800 | C19: 2800 | D19: 0 | E19: 2700 | F19: 2800 | G19: 3.7037037
A20: Arts, Entert. Recreation (Level 3) | B20: 1300 | C20: 1400 | D20: 7.6923077 | E20: 1200 | F20: 1300 | G20: 8.3333333
... A27: Local Gov't (Level 4) | B27: 1500 | C27: 1500 | D27: 0 | E27: 1400 | F27: 1400 | G27: 0
A28: Agriculture wage and salary jobs NSA (Level 1) (Note 1) | B28: (NA) | C28: (NA) | D28: (NA) | E28: (NA) | F28: (NA) | G28: (NA)
A29: General excise & use tax rev. ($1,000) (Level 1) | B29: (NA) | C29: (NA) | D29: (NA) | E29: (NA) | F29: (NA) | G29: (NA)
A30: Income-individual ($1,000) (Level 1) | B30: (NA) | C30: (NA) | D30: (NA) | E30: (NA) | F30: (NA) | G30: (NA)
A31: Declaration estimated taxes (Level 2) | B31: (NA) | C31: (NA) | D31: (NA) | E31: (NA) | F31: (NA) | G31: (NA)
A32: Payment w/returns (Level 2) | B32: (NA) | C32: (NA) | D32: (NA) | E32: (NA) | F32: (NA) | G32: (NA)
A33: WH tax on wages (Level 2) | B33: (NA) | C33: (NA) | D33: (NA) | E33: (NA) | F33: (NA) | G33: (NA)
A34: Refunds ('-' is relative to State) (Level 2) | B34: (NA) | C34: (NA) | D34: (NA) | E34: (NA) | F34: (NA) | G34: (NA)
A35: Transient accommodations tax ($1,000) (Level 1) | B35: (NA) | C35: (NA) | D35: (NA) | E35: (NA) | F35: (NA) | G35: (NA)
A36: County surcharges ($1,000) (Level 1) (Note 3) | B36: 3594.2213 | C36: 3979.44 | D36: 10.717724 | E36: 23271.635 | F36: 24140.757 | G36: 3.7346866
A37: Private Building Permits ($1,000) (Level 1) [d] [e] | B37: 9599.183 | C37: 12713.595 | D37: 32.444553 | E37: 73611.994 | F37: 76554.612 | G37: 3.9974708
A38: Residential (Level 2) [d] [e] | B38: 9599.183 | C38: 12713.595 | D38: 32.444553 | E38: 73611.994 | F38: 76554.612 | G38: 3.9974708
A39: Commercial & industrial (Level 2) [d] [e] [f] | B39: (NA) | C39: (NA) | D39: (NA) | E39: (NA) | F39: (NA) | G39: (NA)
A40: Additions & alterations (Level 2) [d] [e] [f] | B40: (NA) | C40: (NA) | D40: (NA) | E40: (NA) | F40: (NA) | G40: (NA)
A41: Single-family home resales (Level 1) | B41: 34 | C41: 35 | D41: 2.9411765 | E41: 233 | F41: 210 | G41: -9.8712446
A42: Median selling price (Level 2) | B42: 1212500 | C42: 1195000 | D42: -1.443299 | E42: 1175000 | F42: 1300000 | G42: 10.638298
A43: Inventory (aver. units on market) (Level 2) [g] | B43: (NA) | C43: (NA) | D43: (NA) | E43: (NA) | F43: (NA) | G43: (NA)
A44: Condo/Apt/Townhouse units resales (Level 1) | B44: 20 | C44: 18 | D44: -10 | E44: 177 | F44: 137 | G44: -22.59887
A45: Median price (Level 2) | B45: 795000 | C45: 901938 | D45: 13.451321 | E45: 831000 | F45: 845000 | G45: 1.6847172
A46: Inventory (aver. units on market) (Level 2) [g] | B46: (NA) | C46: (NA) | D46: (NA) | E46: (NA) | F46: (NA) | G46: (NA)
...

Sheet MEI 2026-07 ADA2 FY
A1: MONTHLY ECONOMIC INDICATORS: BY MONTH AND FISCAL YEAR_AUGUST 27, 2026
A2: MONTH OF JULY 2026
A3: GEOGRAPHY | B3: Category | C3: JULY 2025 | D3: JULY 2026 | E3: Month Percentage Change | F3: July 2025 through June 2026 FISCAL YEAR YTD | G3: July 2026 through July 2026 FISCAL YEAR YTD | H3: FISCAL YEAR YTD Percentage Change
A4: State | B4: State general fund tax revenues ($1,000) | C4: 755000.27 | D4: (NA) | E4: (NA) | F4: 755000.27 | G4: (NA) | H4: (NA)
A5: State | B5: General excise & use tax rev. ($1,000) | C5: 431543.14 | D5: 463441.84 | E5: 7.3917765 | F5: 431543.14 | G5: 463441.84 | H5: 7.3917765
A6: State | B6: Income-individual ($1,000) | C6: 348930.08 | D6: 332493.08 | E6: -4.7106859 | F6: 348930.08 | G6: 332493.08 | H6: -4.7106859
A7: State | B7: Declaration estimated taxes | C7: 162125.5 | D7: 148372.97 | E7: -8.4826405 | F7: 162125.5 | G7: 148372.97 | H7: -8.4826405
A8: State | B8: Payment w/returns | C8: 7188.736 | D8: 6652.0847 | E8: -7.4651687 | F8: 7188.736 | G8: 6652.0847 | H8: -7.4651687
A9: State | B9: WH tax on wages | C9: 217290.78 | D9: 195301.87 | E9: -10.119576 | F9: 217290.78 | G9: 195301.87 | H9: -10.119576
A10: State | B10: Refunds ('-' is relative to State) | C10: 236125.24 | D10: 208357.05 | E10: -11.759945 | F10: 236125.24 | G10: 208357.05 | H10: -11.759945
A11: State | B11: Transient accommodations tax ($1,000) | C11: 74454.546 | D11: 85506.664 | E11: 14.844114 | F11: 74454.546 | G11: 85506.664 | H11: 14.844114
A12: State | B12: County surcharges ($1,000) (Note 1) | C12: 51730.288 | D12: 55917.589 | E12: 8.0944862 | F12: 51730.288 | G12: 55917.589 | H12: 8.0944862
A13: Honolulu | B13: General excise & use tax rev. ($1,000) | C13: (NA) | D13: (NA) | E13: (NA) | F13: (NA) | G13: (NA) | H13: (NA)
A14: Honolulu | B14: Income-individual ($1,000) | C14: (NA) | D14: (NA) | E14: (NA) | F14: (NA) | G14: (NA) | H14: (NA)
A15: Honolulu | B15: Declaration estimated taxes | C15: (NA) | D15: (NA) | E15: (NA) | F15: (NA) | G15: (NA) | H15: (NA)
A16: Honolulu | B16: Payment w/returns | C16: (NA) | D16: (NA) | E16: (NA) | F16: (NA) | G16: (NA) | H16: (NA)
A17: Honolulu | B17: WH tax on wages | C17: (NA) | D17: (NA) | E17: (NA) | F17: (NA) | G17: (NA) | H17: (NA)
A18: Honolulu | B18: Refunds ('-' is relative to State) | C18: (NA) | D18: (NA) | E18: (NA) | F18: (NA) | G18: (NA) | H18: (NA)
A19: Honolulu | B19: Transient accommodations tax ($1,000) | C19: (NA) | D19: (NA) | E19: (NA) | F19: (NA) | G19: (NA) | H19: (NA)
A20: Honolulu | B20: County surcharges ($1,000) (Note 1) | C20: 33384.829 | D20: 35738.05 | E20: 7.048772 | F20: 33384.829 | G20: 340048.45 | H20: 918.57178
A21: Hawaii County | B21: General excise & use tax rev. ($1,000) | C21: (NA) | D21: (NA) | E21: (NA) | F21: (NA) | G21: (NA) | H21: (NA)
A22: Hawaii County | B22: Income-individual ($1,000) | C22: (NA) | D22: (NA) | E22: (NA) | F22: (NA) | G22: (NA) | H22: (NA)
A23: Hawaii County | B23: Declaration estimated taxes | C23: (NA) | D23: (NA) | E23: (NA) | F23: (NA) | G23: (NA) | H23: (NA)
A24: Hawaii County | B24: Payment w/returns | C24: (NA) | D24: (NA) | E24: (NA) | F24: (NA) | G24: (NA) | H24: (NA)
A25: Hawaii County | B25: WH tax on wages | C25: (NA) | D25: (NA) | E25: (NA) | F25: (NA) | G25: (NA) | H25: (NA)
A26: Hawaii County | B26: Refunds ('-' is relative to State) | C26: (NA) | D26: (NA) | E26: (NA) | F26: (NA) | G26: (NA) | H26: (NA)
A27: Hawaii County | B27: Transient accommodations tax ($1,000) | C27: (NA) | D27: (NA) | E27: (NA) | F27: (NA) | G27: (NA) | H27: (NA)
A28: Hawaii County | B28: County surcharges ($1,000) (Note 1) | C28: 33384.829 | D28: 7506.022 | E28: -77.516668 | F28: 7002.4426 | G28: 73380.941 | H28: 947.93349
A29: Maui | B29: General excise & use tax rev. ($1,000) | C29: (NA) | D29: (NA) | E29: (NA) | F29: (NA) | G29: (NA) | H29: (NA)
A30: Maui | B30: Income-individual ($1,000) | C30: (NA) | D30: (NA) | E30: (NA) | F30: (NA) | G30: (NA) | H30: (NA)
A31: Maui | B31: Declaration estimated taxes | C31: (NA) | D31: (NA) | E31: (NA) | F31: (NA) | G31: (NA) | H31: (NA)
A32: Maui | B32: Payment w/returns | C32: (NA) | D32: (NA) | E32: (NA) | F32: (NA) | G32: (NA) | H32: (NA)
A33: Maui | B33: WH tax on wages | C33: (NA) | D33: (NA) | E33: (NA) | F33: (NA) | G33: (NA) | H33: (NA)
A34: Maui | B34: Refunds ('-' is relative to State) | C34: (NA) | D34: (NA) | E34: (NA) | F34: (NA) | G34: (NA) | H34: (NA)
A35: Maui | B35: Transient accommodations tax ($1,000) | C35: (NA) | D35: (NA) | E35: (NA) | F35: (NA) | G35: (NA) | H35: (NA)
A36: Maui | B36: County surcharges ($1,000) (Note 1) | C36: 7748.7947 | D36: 8694.077 | E36: 12.199088 | F36: 7748.7947 | G36: 82228.858 | H36: 961.18255
A37: Kauai | B37: General excise & use tax rev. ($1,000) | C37: (NA) | D37: (NA) | E37: (NA) | F37: (NA) | G37: (NA) | H37: (NA)
A38: Kauai | B38: Income-individual ($1,000) | C38: (NA) | D38: (NA) | E38: (NA) | F38: (NA) | G38: (NA) | H38: (NA)
A39: Kauai | B39: Declaration estimated taxes | C39: (NA) | D39: (NA) | E39: (NA) | F39: (NA) | G39: (NA) | H39: (NA)
A40: Kauai | B40: Payment w/returns | C40: (NA) | D40: (NA) | E40: (NA) | F40: (NA) | G40: (NA) | H40: (NA)
...
